Workbook

Sheet Summary
A1: Healthcare chatbot evidence — analytical summary
A2: From User Experience to Organizational Value: A Critical Integrative Review of Intelligent Chatbots in Healthcare Services
A5: Historical analytical set | B5: Count | C5: Share | E5: Claim-level disposition | F5: Count | G5: Share
A6: Healthcare-specific reports | B6: =COUNTA('Core coding'!A5:A26) -> 22 | C6: =B6/$B$6 -> 1 | E6: Supported within tested conditions | F6: =COUNTIF('Claim dispositions'!$E$5:$E$22,E6) -> 2 | G6: =F6/$F$10 -> 0.11111111
A7: User measures | B7: =SUM('Core coding'!L5:L26) -> 22 | C7: =B7/$B$6 -> 1 | E7: Supported with qualifications | F7: =COUNTIF('Claim dispositions'!$E$5:$E$22,E7) -> 7 | G7: =F7/$F$10 -> 0.38888889
A8: Clinical measures | B8: =SUM('Core coding'!M5:M26) -> 11 | C8: =B8/$B$6 -> 0.5 | E8: Not established | F8: =COUNTIF('Claim dispositions'!$E$5:$E$22,E8) -> 7 | G8: =F8/$F$10 -> 0.38888889
A9: Referral-safety proxy | B9: =SUM('Core coding'!N5:N26) -> 1 | C9: =B9/$B$6 -> 0.045454545 | E9: Not assessed | F9: =COUNTIF('Claim dispositions'!$E$5:$E$22,E9) -> 2 | G9: =F9/$F$10 -> 0.11111111
A10: Health-system operations | B10: =SUM('Core coding'!Q5:Q26) -> 1 | C10: =B10/$B$6 -> 0.045454545 | E10: Total specified claims | F10: =COUNTA('Claim dispositions'!A5:A22) -> 18
A11: Patient productivity | B11: =SUM('Core coding'!R5:R26) -> 1 | C11: =B11/$B$6 -> 0.045454545 | E11: Worked cases | F11: =COUNTA('Worked cases'!A5:A13) -> 9
A12: Intervention-comparison family | B12: =SUM('Core coding'!K5:K26) -> 7 | C12: =B12/$B$6 -> 0.31818182
A13: Mental health and well-being | B13: =COUNTIF('Core coding'!E5:E26,"Mental health and well-being") -> 13 | C13: =B13/$B$6 -> 0.59090909
A16: Targeted source checks | B16: Count | C16: Access / scope | E16: Reading guide
A17: Historical reports | B17: =COUNTIF('Source checks'!$A$5:$A$33,"S01")+COUNTIF('Source checks'!$A$5:$A$33,"S02")+COUNTIF('Source checks'!$A$5:$A$33,"S03")+COUNTIF('Source checks'!$A$5:$A$33,"S04")+COUNTIF('Source checks'!$A$5:$A$33,"S05")+COUNTIF('Source checks'!$A$5:$A$33,"S08")+COUNTIF('Source checks'!$A$5:$A$33,"S09")+COUNTIF('Source checks'!$A$5:$A$33,"S10")+COUNTIF('Source checks'!$A$5:$A$33,"S11")+COUNTIF('Source checks'!$A$5:$A$33,"S12")+COUNTIF('Source checks'!$A$5:$A$33,"S13")+COUNTIF('Source checks'!$A$5:$A$33,"S14")+COUNTIF('Source checks'!$A$5:$A$33,"S15")+COUNTIF('Source checks'!$A$5:$A$33,"S16")+COUNTIF('Source checks'!$A$5:$A$33,"S17")+COUNTIF('Source checks'!$A$5:$A$33,"S18")+COUNTIF('Source checks'!$A$5:$A$33,"S19")+COUNTIF('Source checks'!$A$5:$A$33,"S20")+COUNTIF('Source checks'!$A$5:$A$33,"S21")+COUNTIF('Source checks'!$A$5:$A$33,"S22")+COUNTIF('Source checks'!$A$5:$A$33,"S23")+COUNTIF('Source checks'!$A$5:$A$33,"S24") -> 22 | C17: Field-specific source checks; not duplicate human appraisal | E17: Use the report and claim sheets to trace measured endpoints, sources, interpretation boundaries, and the next evidence needed. Unknown fields are not zero and observations are not automatically causal effects.
A18: Contemporary examples | B18: =COUNTIF('Source checks'!$A$5:$A$33,"U01")+COUNTIF('Source checks'!$A$5:$A$33,"U02")+COUNTIF('Source checks'!$A$5:$A$33,"U03")+COUNTIF('Source checks'!$A$5:$A$33,"U04") -> 4 | C18: Outside historical denominators
A19: Established frameworks | B19: =B20-B17-B18 -> 3 | C19: Proctor, NASSS, NICE
A20: All source-check records | B20: =COUNTA('Source checks'!A5:A33) -> 29 | C20: Different access levels
A23: Interpretive boundary
A24: Counts describe a fixed, non-exhaustive report corpus. Source checks are field-specific and were not duplicated by independent human reviewers. Sensitivity labels are not formal risk-of-bias ratings. The proposed worksheet is not independently validated. CSV data and analytical scripts are authoritative; workbook reproduction uses only the Python standard library.
A29: Reproduce: python 03_code/reproduce.py | Rebuild workbook: python 03_code/build_workbook.py | Tests: python -m unittest discover -s 03_code -p "test_*.py" -v

Sheet Core coding
A1: Core coding
A2: Source: 01_data/coding_revised_core22.csv. Report-level evidence; source-access limits and analytic roles are retained.
A4: study_id | B4: year | C4: title | D4: doi | E4: domain | F4: design_family | G4: geographic_context | H4: legacy_confidence | I4: role | J4: core_flag | K4: comparative | L4: user_outcome | M4: clinical_outcome | N4: safety_focused_investigation | O4: response_accuracy_benchmark | P4: referral_intention_proxy | Q4: health_system_operations | R4: patient_productivity | S4: source_url | T4: verification_status | U4: independent_human_review | V4: legacy_service_flag | W4: legacy_safety_flag | X4: legacy_org_flag
A5: S01 | B5: 2019 | C5: Physicians’ perceptions of chatbots in health care: cross-sectional web-based survey | D5: 10.2196/12887 | E5: General healthcare adoption/information | F5: Survey/observational | G5: United States | H5: Moderate | I5: bounded_healthcare_sample | J5: 1 | K5: 0 | L5: 1 | M5: 0 | N5: 0 | O5: 0 | P5: 0 | Q5: 0 | R5: 0 | S5: https://doi.org/10.2196/12887 | T5: Targeted current primary-source check; see source_verification_v2.csv for exact fields and access level. No independent human review. | U5: Not documented | V5: 0 | W5: 0 | X5: 0
A6: S02 | B6: 2019 | C6: Acceptability of artificial intelligence (AI)-led chatbot services in healthcare: a mixed-methods study | D6: 10.1177/2055207619871808 | E6: General healthcare adoption/information | F6: Mixed methods | G6: United Kingdom | H6: Moderate | I6: bounded_healthcare_sample | J6: 1 | K6: 0 | L6: 1 | M6: 0 | N6: 0 | O6: 0 | P6: 0 | Q6: 0 | R6: 0 | S6: https://doi.org/10.1177/2055207619871808 | T6: Targeted current primary-source check; see source_verification_v2.csv for exact fields and access level. No independent human review. | U6: Not documented | V6: 0 | W6: 0 | X6: 0
A7: S03 | B7: 2019 | C7: A chatbot system for mental healthcare based on SAT counseling method | D7: 10.1155/2019/9517321 | E7: Mental health and well-being | F7: Randomized/comparative intervention | G7: Japan | H7: Lower | I7: bounded_healthcare_sample | J7: 1 | K7: 1 | L7: 1 | M7: 1 | N7: 0 | O7: 0 | P7: 0 | Q7: 0 | R7: 0 | S7: https://doi.org/10.1155/2019/9517321 | T7: Targeted current primary-source check; specified fields/access level in source_verification_v2.csv; no independent human review. | U7: Not documented | V7: 0 | W7: 0 | X7: 0
A8: S04 | B8: 2019 | C8: Considering patient safety in autonomous e-mental health systems—detecting risk situations and referring patients back to human care | D8: 10.1186/s12911-019-0796-x | E8: Mental health and well-being | F8: Mixed methods | G8: Netherlands/online international sample | H8: Moderate | I8: bounded_healthcare_sample | J8: 1 | K8: 0 | L8: 1 | M8: 0 | N8: 1 | O8: 0 | P8: 1 | Q8: 0 | R8: 0 | S8: https://doi.org/10.1186/s12911-019-0796-x | T8: Targeted current primary-source check; see source_verification_v2.csv for exact fields and access level. No independent human review. | U8: Not documented | V8: 1 | W8: 1 | X8: 0
A9: S05 | B9: 2019 | C9: A chatbot versus physicians to provide information for patients with breast cancer: blind, randomized controlled noninferiority trial | D9: 10.2196/15787 | E9: Oncology information services | F9: Randomized/comparative intervention | G9: France | H9: Higher | I9: bounded_healthcare_sample | J9: 1 | K9: 1 | L9: 1 | M9: 0 | N9: 0 | O9: 0 | P9: 0 | Q9: 0 | R9: 0 | S9: https://doi.org/10.2196/15787 | T9: Targeted current primary-source check; see source_verification_v2.csv for exact fields and access level. No independent human review. | U9: Not documented | V9: 1 | W9: 1 | X9: 0
A10: S08 | B10: 2020 | C10: Physicians’ perceptions of the use of a chatbot for information seeking: qualitative study | D10: 10.2196/15185 | E10: General healthcare adoption/information | F10: Qualitative | G10: France | H10: Moderate | I10: bounded_healthcare_sample | J10: 1 | K10: 0 | L10: 1 | M10: 0 | N10: 0 | O10: 0 | P10: 0 | Q10: 0 | R10: 0 | S10: https://doi.org/10.2196/15185 | T10: Targeted current primary-source check; see source_verification_v2.csv for exact fields and access level. No independent human review. | U10: Not documented | V10: 0 | W10: 0 | X10: 0
A11: S09 | B11: 2020 | C11: Preliminary evaluation of the engagement and effectiveness of a mental health chatbot | D11: 10.3389/fdgth.2020.576361 | E11: Mental health and well-being | F11: Single-arm/pre-post intervention | G11: Brazil | H11: Lower | I11: bounded_healthcare_sample | J11: 1 | K11: 0 | L11: 1 | M11: 1 | N11: 0 | O11: 0 | P11: 0 | Q11: 0 | R11: 0 | S11: https://doi.org/10.3389/fdgth.2020.576361 | T11: Targeted current primary-source check; see source_verification_v2.csv for exact fields and access level. No independent human review. | U11: Not documented | V11: 1 | W11: 0 | X11: 0
A12: S10 | B12: 2020 | C12: AI-powered mental health chatbots: examining users’ motivations, active communicative action and engagement after mass-shooting disasters | D12: 10.1111/1468-5973.12319 | E12: Mental health and well-being | F12: Survey/observational | G12: United States | H12: Moderate | I12: bounded_healthcare_sample | J12: 1 | K12: 0 | L12: 1 | M12: 0 | N12: 0 | O12: 0 | P12: 0 | Q12: 0 | R12: 0 | S12: https://doi.org/10.1111/1468-5973.12319 | T12: Targeted current primary-source check; see source_verification_v2.csv for exact fields and access level. No independent human review. | U12: Not documented | V12: 0 | W12: 0 | X12: 0
A13: S11 | B13: 2020 | C13: Implementation of a digital chatbot to screen health system employees during the COVID-19 pandemic | D13: 10.1093/jamia/ocaa130 | E13: Public health | F13: Implementation/technical evaluation | G13: United States | H13: Moderate | I13: bounded_healthcare_sample | J13: 1 | K13: 0 | L13: 1 | M13: 0 | N13: 0 | O13: 0 | P13: 0 | Q13: 1 | R13: 0 | S13: https://doi.org/10.1093/jamia/ocaa130 | T13: Targeted current primary-source check; see source_verification_v2.csv for exact fields and access level. No independent human review. | U13: Not documented | V13: 1 | W13: 0 | X13: 1
A14: S12 | B14: 2021 | C14: A therapeutic relational agent for reducing problematic substance use (Woebot): development and usability study | D14: 10.2196/24850 | E14: Mental health and well-being | F14: Single-arm/pre-post intervention | G14: United States | H14: Lower | I14: bounded_healthcare_sample | J14: 1 | K14: 0 | L14: 1 | M14: 1 | N14: 0 | O14: 0 | P14: 0 | Q14: 0 | R14: 0 | S14: https://doi.org/10.2196/24850 | T14: Targeted current primary-source check; see source_verification_v2.csv for exact fields and access level. No independent human review. | U14: Not documented | V14: 1 | W14: 0 | X14: 0
A15: S13 | B15: 2021 | C15: Utilization of self-diagnosis health chatbots in real-world settings: case study | D15: 10.2196/19928 | E15: General healthcare adoption/information | F15: Survey/observational | G15: China | H15: Moderate | I15: bounded_healthcare_sample | J15: 1 | K15: 0 | L15: 1 | M15: 0 | N15: 0 | O15: 0 | P15: 0 | Q15: 0 | R15: 0 | S15: https://doi.org/10.2196/19928 | T15: Targeted current primary-source check; see source_verification_v2.csv for exact fields and access level. No independent human review. | U15: Not documented | V15: 1 | W15: 0 | X15: 0
A16: S14 | B16: 2021 | C16: Can chatbots help support a person’s mental health? Perceptions and views from mental healthcare professionals and experts | D16: 10.1145/3453175 | E16: Mental health and well-being | F16: Survey/observational | G16: Northern Ireland, Ireland, Scotland, Sweden and Finland | H16: Moderate | I16: bounded_healthcare_sample | J16: 1 | K16: 0 | L16: 1 | M16: 0 | N16: 0 | O16: 0 | P16: 0 | Q16: 0 | R16: 0 | S16: https://doi.org/10.1145/3453175 | T16: Targeted current primary-source check; specified fields/access level in source_verification_v2.csv; no independent human review. | U16: Not documented | V16: 0 | W16: 0 | X16: 0
... A26: S24 | B26: 2024 | C26: Development and evaluation of a smartphone-based chatbot coach to facilitate a balanced lifestyle in individuals with headaches (BalanceUP App): randomized controlled trial | D26: 10.2196/50132 | E26: Chronic-condition self-management | F26: Randomized/comparative intervention | G26: Switzerland | H26: Higher | I26: bounded_healthcare_sample | J26: 1 | K26: 1 | L26: 1 | M26: 1 | N26: 0 | O26: 0 | P26: 0 | Q26: 0 | R26: 1 | S26: https://doi.org/10.2196/50132 | T26: Targeted current primary-source check; see source_verification_v2.csv for exact fields and access level. No independent human review. | U26: Not documented | V26: 1 | W26: 0 | X26: 0

Sheet Report roster
A1: Report roster
A2: Source: 01_data/full_study_roster26.csv. Report-level evidence; source-access limits and analytic roles are retained.
A4: Study ID | B4: Citation | C4: Year | D4: Title | E4: DOI | F4: System | G4: Domain | H4: Country/region | I4: Stakeholder | J4: Design | K4: Design family | L4: Sample summary | M4: Comparator | N4: Duration/follow-up | O4: Interpretive confidence | P4: Source URL | Q4: Revised role | R4: Current verification | S4: Independent verification | T4: Full bibliographic citation | U4: Legacy reference number | V4: Legacy eligibility
A5: S01 | B5: Palanica et al. (2019) | C5: 2019 | D5: Physicians’ perceptions of chatbots in health care: cross-sectional web-based survey | E5: 10.2196/12887 | F5: Generic health chatbots (scenario-based) | G5: General healthcare adoption | H5: United States | I5: Physicians | J5: Cross-sectional web survey | K5: Survey/observational | L5: Recruited: 100; randomized: N/A; completed: 100; analyzed: 100 | M5: None | N5: Single survey | O5: Moderate | P5: https://doi.org/10.2196/12887 | Q5: bounded_healthcare_sample | R5: Targeted primary full text recheck, 23 October 2026: Results; Tables 1–6. Scope: 100 physician survey respondents; perceived task suitability and risks, not observed patient improvement. Not a full independent appraisal. | S5: Not documented | T5: Palanica A, Flaschner P, Thommandram A, Li M, Fossat Y. Physicians’ perceptions of chatbots in health care: cross-sectional web-based survey. J Med Internet Res. 2019;21(4):e12887. doi:10.2196/12887. | U5: [14] | V5: Working inclusion
A6: S02 | B6: Nadarzynski et al. (2019) | C6: 2019 | D6: Acceptability of artificial intelligence (AI)-led chatbot services in healthcare: a mixed-methods study | E6: 10.1177/2055207619871808 | F6: Generic health chatbot demonstration | G6: General healthcare adoption | H6: United Kingdom | I6: Potential healthcare users | J6: Mixed methods: interviews plus online survey | K6: Mixed methods | L6: 29 qualitative interviews; abstract survey N = 216; Results/Table 2 analyzed survey n = 215. Components are separate; participant totals are not pooled. | M6: None | N6: Single interview/survey | O6: Moderate | P6: https://doi.org/10.1177/2055207619871808 | Q6: bounded_healthcare_sample | R6: Targeted primary full text recheck, 23 October 2026: Results; quantitative sub-study; Table 2. Scope: 29 interviews; 215 analyzed survey respondents. Abstract mentions 216; the analyzed survey table uses 215. Not a full independent appraisal. | S6: Not documented | T6: Nadarzynski T, Miles O, Cowie A, Ridge D. Acceptability of artificial intelligence-led chatbot services in healthcare: a mixed-methods study. Digit Health. 2019;5:2055207619871808. doi:10.1177/2055207619871808. | U6: [41] | V6: Working inclusion
A7: S03 | B7: Kamita et al. (2019) | C7: 2019 | D7: A chatbot system for mental healthcare based on SAT counseling method | E7: 10.1155/2019/9517321 | F7: SAT counseling chatbot | G7: Mental health | H7: Japan | I7: Adult users | J7: Small randomized comparative experiment | K7: Randomized/comparative intervention | L7: 27 college students randomly assigned: chatbot n = 15; web control n = 12; one-session evaluation. | M7: Nonconversational web-based counseling information | N7: Single short-use session | O7: Lower | P7: https://doi.org/10.1155/2019/9517321 | Q7: bounded_healthcare_sample | R7: Targeted primary full text in publisher indexed record check, 23 October 2026: Sections 6.2–6.3; Table 3. 27 students randomly assigned 15/12; one-session SAT course; pre/post mental measures and TAM-based user motivation; not longitudinal use. No independent human duplicate assessment. | S7: Not documented | T7: Kamita, T., Ito, T., Matsumoto, A., Munakata, T. and Inoue, T., 2019. A chatbot system for mental healthcare based on SAT counseling method. Mobile Information Systems, 2019(1), p.9517321. https://doi.org/10.1155/2019/9517321 | U7: [60] | V7: Working inclusion
A8: S04 | B8: Tielman et al. (2019) | C8: 2019 | D8: Considering patient safety in autonomous e-mental health systems—detecting risk situations and referring patients back to human care | E8: 10.1186/s12911-019-0796-x | F8: Autonomous e-mental health virtual agent/referral scenarios | G8: Mental health safety and escalation | H8: Netherlands/online international sample | I8: Experts and potential users | J8: Formative qualitative study plus factorial vignette experiment | K8: Mixed methods | L8: Recruited: 8 experts; 229 online participants recruited; randomized: Factorial vignette assignment; completed: 160 online participants included; analyzed: 8 experts; 160 participants | M8: Alternative risk severity, agent response and referral strategies | N8: Single vignette experiment | O8: Moderate | P8: https://doi.org/10.1186/s12911-019-0796-x | Q8: bounded_healthcare_sample | R8: Targeted primary full text recheck, 23 October 2026: Experimental method; dependent measures. Scope: 160 participants in referral-intention experiment; intended self-referral, not verified completed referral. Not a full independent appraisal. | S8: Not documented | T8: Tielman ML, Neerincx MA, Pagliari C, Rizzo A, Brinkman WP. Considering patient safety in autonomous e-mental health systems: detecting risk situations and referring patients back to human care. BMC Med Inform Decis Mak. 2019;19:47. doi:10.1186/s12911-019-0796-x. | U8: [17] | V8: Working inclusion
A9: S05 | B9: Bibault et al. (2019) | C9: 2019 | D9: A chatbot versus physicians to provide information for patients with breast cancer: blind, randomized controlled noninferiority trial | E9: 10.2196/15787 | F9: Vik | G9: Oncology information service | H9: France | I9: Women with breast cancer | J9: Blind randomized noninferiority trial | K9: Randomized/comparative intervention | L9: Recruited: 142; randomized: 142 (71/71); completed: 142; analyzed: 142 | M9: Multidisciplinary physicians’ written answers | N9: Single information assessment | O9: Higher | P9: https://doi.org/10.2196/15787 | Q9: bounded_healthcare_sample | R9: Targeted primary full text recheck, 23 October 2026: Methods: Procedures/Outcomes; Results. Scope: 142 randomized 71/71; overall information-satisfaction noninferiority with 10% margin, 69% versus 64% success; predefined prechecked answers. Not a full independent appraisal. | S9: Not documented | T9: Bibault JE, Chaix B, Guillemassé A, et al. A chatbot versus physicians to provide information for patients with breast cancer: blind, randomized controlled noninferiority trial. J Med Internet Res. 2019;21(11):e15787. doi:10.2196/15787. | U9: [66] | V9: Working inclusion
A10: S06 | B10: Kocaballi et al. (2020) | C10: 2020 | D10: Responses of conversational agents to health and lifestyle prompts: investigation of appropriateness and presentation structures | E10: 10.2196/15823 | F10: Eight commercially available conversational agents | G10: Medical information and safety | H10: Australia-based research; global products | I10: Potential consumers | J10: Content/response evaluation | K10: Content/technical evaluation | L10: Recruited: 30 prompts; randomized: N/A; completed: 240 agent responses; analyzed: 240 responses | M10: Across agents and prompt categories | N10: Point-in-time test | O10: Moderate | P10: https://doi.org/10.2196/15823 | Q10: contextual_assistant_benchmark | R10: Targeted primary-source check in this revision | S10: Not documented | T10: Kocaballi AB, Quiroz JC, Rezazadegan D, et al. Responses of conversational agents to health and lifestyle prompts: investigation of appropriateness and presentation structures. J Med Internet Res. 2020;22(2):e15823. doi:10.2196/15823. | U10: [3] | V10: Working inclusion
A11: S07 | B11: Ferrand et al. (2020) | C11: 2020 | D11: Evaluating smart assistant responses for accuracy and misinformation regarding human papillomavirus vaccination: content analysis study | E11: 10.2196/19018 | F11: Four smart assistants | G11: Vaccination information | H11: United States | I11: Potential consumers | J11: Content analysis | K11: Content/technical evaluation | L11: Recruited: 10 questions across four assistants; randomized: N/A; completed: 103 analyzable responses; analyzed: 103 responses | M11: Across assistants/questions | N11: Point-in-time test | O11: Moderate | P11: https://doi.org/10.2196/19018 | Q11: contextual_assistant_benchmark | R11: Targeted primary-source check in this revision | S11: Not documented | T11: Ferrand J, Hockensmith R, Houghton RF, Walsh-Buhi ER. Evaluating smart assistant responses for accuracy and misinformation regarding human papillomavirus vaccination: content analysis study. J Med Internet Res. 2020;22(8):e19018. doi:10.2196/19018. | U11: [58] | V11: Working inclusion
A12: S08 | B12: Koman et al. (2020) | C12: 2020 | D12: Physicians’ perceptions of the use of a chatbot for information seeking: qualitative study | E12: 10.2196/15185 | F12: Information-seeking chatbot prototype | G12: Professional medical information | H12: France | I12: Physicians | J12: Qualitative interviews | K12: Qualitative | L12: Recruited: 10; randomized: N/A; completed: 10; analyzed: 8 general practitioners; 2 specialists | M12: None | N12: Single demonstration and interview | O12: Moderate | P12: https://doi.org/10.2196/15185 | Q12: bounded_healthcare_sample | R12: Targeted primary full text recheck, 23 October 2026: Results: Demographics; Discussion. Scope: 10 French healthcare professionals interviewed about information-seeking chatbot; qualitative user evidence. Not a full independent appraisal. | S12: Not documented | T12: Koman J, Fauvelle K, Schuck S, Texier N, Mebarki A. Physicians’ perceptions of the use of a chatbot for information seeking: qualitative study. J Med Internet Res. 2020;22(11):e15185. doi:10.2196/15185. | U12: [18] | V12: Working inclusion
A13: S09 | B13: Daley et al. (2020) | C13: 2020 | D13: Preliminary evaluation of the engagement and effectiveness of a mental health chatbot | E13: 10.3389/fdgth.2020.576361 | F13: Vitalk (Viki) | G13: Mental health | H13: Brazil | I13: Adult Portuguese-speaking users | J13: Uncontrolled real-world pre-post analysis | K13: Single-arm/pre-post intervention | L13: Retrospective completer cohort: 3,629 users completed the first 30-day program phase and were analyzed. Initial recruitment or installation denominator: not reported; not inferred from the completer cohort. No randomization. | M13: None | N13: 30-day first program phase | O13: Lower | P13: https://doi.org/10.3389/fdgth.2020.576361 | Q13: bounded_healthcare_sample | R13: Primary full text rechecked on 23 October 2026; 3,629 first-phase completers analyzed, not an enrollment denominator. Initial recruitment population not reported. | S13: Not documented | T13: Daley, K., Hungerbuehler, I., Cavanagh, K., Claro, H.G., Swinton, P.A. and Kapps, M., 2020. Preliminary evaluation of the engagement and effectiveness of a mental health chatbot. Frontiers in Digital Health, 2, 576361. https://doi.org/10.3389/fdgth.2020.576361 | U13: [68] | V13: Working inclusion
A14: S10 | B14: Cheng and Jiang (2020) | C14: 2020 | D14: AI-powered mental health chatbots: examining users’ motivations, active communicative action and engagement after mass-shooting disasters | E14: 10.1111/1468-5973.12319 | F14: AI-powered mental-health chatbot services | G14: Mental health/crisis communication | H14: United States | I14: Chatbot users | J14: Cross-sectional survey | K14: Survey/observational | L14: Recruited: 1,114; randomized: N/A; completed: 1,114; analyzed: 1,114 | M14: None | N14: Single survey | O14: Moderate | P14: https://doi.org/10.1111/1468-5973.12319 | Q14: bounded_healthcare_sample | R14: Targeted primary abstract recheck, 23 October 2026: Abstract. Scope: 1114 US participants surveyed; motivation, communication and engagement associations. Detailed attrition not re-extracted. Not a full independent appraisal. | S14: Not documented | T14: Cheng, Y. and Jiang, H., 2020. AI‐Powered mental health chatbots: Examining users’ motivations, active communicative action and engagement after mass‐shooting disasters. Journal of Contingencies and Crisis Management, 28(3), pp.339-354. https://doi.org/10.1111/1468-5973.12319 | U14: [61] | V14: Working inclusion
A15: S11 | B15: Judson et al. (2020) | C15: 2020 | D15: Implementation of a digital chatbot to screen health system employees during the COVID-19 pandemic | E15: 10.1093/jamia/ocaa130 | F15: COVID-19 employee screening chatbot | G15: Public health/occupational screening | H15: United States | I15: Health-system employees and occupational-health teams | J15: Implementation case study | K15: Implementation/technical evaluation | L15: Operational deployment; direct entrance-clearance timing: manual n = 28, digital n = 20. Mean clearance 48 versus 8 seconds; peak-shift mean queue 8 minutes 20 seconds versus 1 minute 40 seconds. | M15: Nonrandomized manual-versus-digital entrance-clearance comparison; peak-shift queue comparison during implementation. | N15: Initial pandemic deployment period | O15: Moderate | P15: https://doi.org/10.1093/jamia/ocaa130 | Q15: bounded_healthcare_sample | R15: Targeted primary full-text recheck, 23 October 2026: Results: Impact on Operations; Discussion: limitations. This is not independent duplicate human extraction. | S15: Not documented | T15: Judson TJ, Odisho AY, Young JJ, et al. Implementation of a digital chatbot to screen health system employees during the COVID-19 pandemic. J Am Med Inform Assoc. 2020;27(9):1450-1455. doi:10.1093/jamia/ocaa130. | U15: [38] | V15: Working inclusion
A16: S12 | B16: Prochaska et al. (2021) | C16: 2021 | D16: A therapeutic relational agent for reducing problematic substance use (Woebot): development and usability study | E16: 10.2196/24850 | F16: Woebot for Substance Use Disorders (W-SUDs) | G16: Mental health/substance use | H16: United States | I16: Adults with problematic substance use | J16: Single-group pre-post intervention | K16: Single-arm/pre-post intervention | L16: Recruited: 3,597 screened; 141 consented; 128 baseline; randomized: N/A; completed: 51 posttreatment respondents; analyzed: 101 analytic sample | M16: None | N16: 8 weeks | O16: Lower | P16: https://doi.org/10.2196/24850 | Q16: bounded_healthcare_sample | R16: Targeted primary full text recheck, 23 October 2026: Abstract; Results: Sample; Table 1. Scope: 101 analytic participants; 51 posttreatment respondents; eight-week single-group intervention with usability and symptom endpoints. Not a full independent appraisal. | S16: Not documented | T16: Prochaska, J.J., Vogel, E.A., Chieng, A., Kendra, M., Baiocchi, M., Pajarito, S. and Robinson, A., 2021. A therapeutic relational agent for reducing problematic substance use (Woebot): development and usability study. Journal of medical Internet research, 23(3), p.e24850. https://doi.org/10.2196/24850 | U16: [7] | V16: Working inclusion
... A30: S26 | B30: Siddals et al. (2024) | C30: 2024 | D30: “It happened to be the perfect thing”: experiences of generative AI chatbots for mental health | E30: 10.1038/s44184-024-00097-4 | F30: Generative AI chatbots used for mental-health support | G30: Mental health/user experience | H30: Self-selected/international; see source | I30: Consumer chatbot users | J30: Qualitative interviews | K30: Qualitative | L30: 19 interviewees | M30: None | N30: Cross-sectional | O30: Not newly appraised | P30: https://doi.org/10.1038/s44184-024-00097-4 | Q30: contextual_consumer_chatbot | R30: Targeted bibliographic/abstract verification | S30: Not documented | T30: Siddals, S., Torous, J. and Coxon, A., 2024. “It happened to be the perfect thing”: experiences of generative AI chatbots for mental health. npj Mental Health Research, 3, 48. https://doi.org/10.1038/s44184-024-00097-4 | U30: Contextual only | V30: Contextual

Sheet Extraction
A1: Extraction
A2: Source: 01_data/extraction_revised24.csv. Report-level evidence; source-access limits and analytic roles are retained.
A4: Study ID | B4: Citation | C4: Year | D4: System | E4: Modality | F4: Technical classification | G4: Domain | H4: Setting | I4: Country/region | J4: Stakeholder | K4: Design | L4: Recruitment | M4: Recruited N | N4: Randomized N | O4: Completed/endpoint N | P4: Analyzed N | Q4: Comparator | R4: Duration/follow-up | S4: Instruments | T4: User outcomes | U4: Service outcomes | V4: Organizational outcomes | W4: Clinical outcomes | X4: Safety/equity outcomes | Y4: Key limitations | Z4: Interpretive confidence | AA4: Source URL | AB4: Revised role | AC4: Correction note | AD4: Inherited reported findings | AE4: Legacy verification note | AF4: Current verification | AG4: Current source locator | AH4: Updated findings
A5: S01 | B5: Palanica et al. (2019) | C5: 2019 | D5: Generic health chatbots (scenario-based) | E5: Survey; no single deployed chatbot | F5: Not system-specific | G5: General healthcare adoption | H5: Practicing physicians | I5: United States | J5: Physicians | K5: Cross-sectional web survey | L5: Online physician survey | M5: 100 | O5: 100 | P5: 100 | Q5: None | R5: Single survey | S5: Study-specific perception questionnaire | T5: Perceived usefulness, limitations, risk and emotional capability | U5: Perceived suitability for scheduling, clinic location and medication information | V5: Professional acceptance and task-allocation preferences | W5: None measured | X5: Concern about incorrect self-diagnosis and inability to address all patient needs | Y5: Perception study; hypothetical use cases; no patient or service outcome measurement. | Z5: Moderate | AA5: https://doi.org/10.2196/12887 | AB5: bounded_healthcare_sample | AD5: Physicians viewed chatbots as more suitable for administrative or information tasks than for diagnosis, emotional support or complex care. | AE5: Publisher abstract/full text; sample, design and main task perceptions verified. | AF5: Targeted primary full text recheck, 23 October 2026: Results; Tables 1–6. Scope: 100 physician survey respondents; perceived task suitability and risks, not observed patient improvement. Not a full independent appraisal. | AG5: Results; Tables 1–6
A6: S02 | B6: Nadarzynski et al. (2019) | C6: 2019 | D6: Generic health chatbot demonstration | E6: Text chatbot demonstration plus interviews and online survey | F6: Not system-specific | G6: General healthcare adoption | H6: University/community internet users | I6: United Kingdom | J6: Potential healthcare users | K6: Mixed methods: interviews plus online survey | L6: University recruitment for interviews; social-media survey | M6: 29 interviews; survey abstract N = 216 | O6: 29 interviews; 215 survey respondents analyzed | P6: 244 across the two components | Q6: None | R6: Single interview/survey | S6: Semi-structured interview; 24-item survey | T6: Acceptability, perceived utility, trust, privacy/security and empathy concerns | U6: Willingness to use chatbots for information, appointment booking and service location | V6: Design requirements for uptake and person-centred implementation | W6: None measured | X6: Concerns about accuracy, cyber-security, confidentiality and lack of empathy | Y6: Convenience and social-media recruitment; largely hypothetical future use; exploratory unadjusted regressions. | Z6: Moderate | AA6: https://doi.org/10.1177/2055207619871808 | AB6: bounded_healthcare_sample | AD6: Sixty-seven percent of survey respondents were likely to use a health chatbot; perceived utility and trustworthiness were associated with acceptability, while poor IT skills and dislike of computer interaction were barriers. | AE6: Publisher full text; component samples, acceptability estimate and main predictors verified. | AF6: Targeted primary full text recheck, 23 October 2026: Results; quantitative sub-study; Table 2. Scope: 29 interviews; 215 analyzed survey respondents. Abstract mentions 216; the analyzed survey table uses 215. Not a full independent appraisal. | AG6: Results; quantitative sub-study; Table 2
A7: S03 | B7: Kamita et al. (2019) | C7: 2019 | D7: SAT counseling chatbot | E7: Web-based text chatbot | F7: Rule-based/SAT counseling dialogue | G7: Mental health | H7: Short experimental evaluation | I7: Japan | J7: College students | K7: Randomized comparative experiment, one session | L7: Convenience experimental sample | M7: 27 | N7: 27 (chatbot n = 15; web control n = 12); random assignment explicitly reported | O7: 27 | P7: Chatbot n = 15; web control n = 12 | Q7: Nonconversational web-based counseling information | R7: Single short-use session | S7: Self-esteem, state anxiety and depressive-symptom measures; technology acceptance items | T7: Ease of use, behavioral intention and interaction experience | U7: None directly measured | V7: None directly measured | W7: Short-term within-session changes in self-esteem, anxiety and depressive symptoms | X7: Not a safety study | Y7: Very small sample (n = 27) and one-session outcomes; random assignment is explicitly reported. Allocation concealment and sequence-generation details are not established in the available verification. | Z7: Lower | AA7: https://doi.org/10.1155/2019/9517321 | AB7: bounded_healthcare_sample | AC7: Random assignment is explicitly described; do not equate this with verified allocation concealment. Small sample and one-session follow-up remain limitations. | AD7: The chatbot group reported favorable short-term psychological and acceptance outcomes relative to its own baseline; the small sample prevents strong effectiveness conclusions. | AE7: Publisher full text; group sizes, design and short-term outcome domains verified. | AF7: Targeted primary full text in publisher indexed record check, 23 October 2026: Sections 6.2–6.3; Table 3. 27 students randomly assigned 15/12; one-session SAT course; pre/post mental measures and TAM-based user motivation; not longitudinal use. No independent human duplicate assessment.
A8: S04 | B8: Tielman et al. (2019) | C8: 2019 | D8: Autonomous e-mental health virtual agent/referral scenarios | E8: Virtual-agent vignettes | F8: Scenario-based referral strategies | G8: Mental health safety and escalation | H8: Expert interviews and crowdsourced vignette experiment | I8: Netherlands/online international sample | J8: Experts and potential users | K8: Formative qualitative study plus factorial vignette experiment | L8: Expert recruitment and Amazon Mechanical Turk | M8: 8 experts; 229 online participants recruited | N8: Factorial vignette assignment | O8: 160 online participants included | P8: 8 experts; 160 participants | Q8: Alternative risk severity, agent response and referral strategies | R8: Single vignette experiment | S8: Self-referral intention, intention to return and feeling heard | T8: Perceived support, return intention and referral intention | U8: Hypothetical intended referral, not completed handoff | V8: Human-care handoff strategy | W8: None measured | X8: Referral-intention proxy, not actual referral or harm | Y8: Vignette-based behavior, crowdsourced sample and no real clinical event or referral completion. | Z8: Moderate | AA8: https://doi.org/10.1186/s12911-019-0796-x | AB8: bounded_healthcare_sample | AC8: An empirical virtual-agent experiment measured intention to self-refer, not actual referral or avoided harm. | AD8: How the virtual agent communicated and referred users affected perceived support and willingness to seek or return to care; the evidence concerns hypothetical scenarios rather than deployed clinical outcomes. | AE8: Publisher full text; expert sample, recruited/analyzed online sample and factorial design verified. | AF8: Targeted primary full text recheck, 23 October 2026: Experimental method; dependent measures. Scope: 160 participants in referral-intention experiment; intended self-referral, not verified completed referral. Not a full independent appraisal. | AG8: Experimental method; dependent measures
A9: S05 | B9: Bibault et al. (2019) | C9: 2019 | D9: Vik | E9: Web-based text responses | F9: NLP/ML-supported oncology information chatbot | G9: Oncology information service | H9: Breast-cancer patient information | I9: France | J9: Women with breast cancer | K9: Blind randomized noninferiority trial | L9: Breast-cancer patient association | M9: 142 | N9: 142 (71/71) | O9: 142 | P9: 142 | Q9: Multidisciplinary physicians’ written answers | R9: Single information assessment | S9: Adapted EORTC QLQ-INFO25 | T9: Information satisfaction and perceived helpfulness | U9: Information satisfaction, not operational effectiveness | V9: Potential adjunct to clinician information workload; not directly measured | W9: None measured | X9: No direct safety/accuracy endpoint; information satisfaction | Y9: Predetermined questions and responses rather than natural live conversation; selected digitally literate population; no clinical outcome. | Z9: Higher | AA9: https://doi.org/10.2196/15787 | AB9: bounded_healthcare_sample | AC9: Primary endpoint is information satisfaction, not observed safety or response accuracy. | AD9: Success rates were 69% for Vik and 64% for physician answers, meeting the prespecified noninferiority criterion for the overall information-satisfaction outcome. | AE9: Publisher full text; randomization, completion, outcome and noninferiority result verified. | AF9: Targeted primary full text recheck, 23 October 2026: Methods: Procedures/Outcomes; Results. Scope: 142 randomized 71/71; overall information-satisfaction noninferiority with 10% margin, 69% versus 64% success; predefined prechecked answers. Not a full independent appraisal. | AG9: Methods: Procedures/Outcomes; Results
A10: S06 | B10: Kocaballi et al. (2020) | C10: 2020 | D10: Eight commercially available conversational agents | E10: Voice/text assistant responses | F10: Commercial general-purpose conversational agents | G10: Medical information and safety | H10: Standardized prompt evaluation | I10: Australia-based research; global products | J10: Potential consumers | K10: Content/response evaluation | L10: Not applicable | M10: 30 prompts | O10: 240 agent responses | P10: 240 responses | Q10: Across agents and prompt categories | R10: Point-in-time test | S10: Appropriateness and presentation-structure coding | T10: Not directly measured | U10: Appropriateness and presentation of responses | V10: None directly measured | W10: None measured | X10: Safety-critical response appropriateness | Y10: Point-in-time product test; no user behavior or clinical outcomes; results may change with software updates. | Z10: Moderate | AA10: https://doi.org/10.2196/15823 | AB10: contextual_assistant_benchmark | AC10: Apply the health-specific system/care-pathway rule consistently. | AD10: Only a minority of responses to safety-critical and lifestyle prompts were judged appropriate, showing that general-purpose agents should not be assumed to provide reliable health guidance. | AE10: Publisher full text; agents, prompt count, response count and appropriateness focus verified. | AF10: Targeted primary-source check in this revision
A11: S07 | B11: Ferrand et al. (2020) | C11: 2020 | D11: Four smart assistants | E11: Voice assistant responses | F11: Commercial smart assistants | G11: Vaccination information | H11: Standardized HPV-vaccine questions | I11: United States | J11: Potential consumers | K11: Content analysis | L11: Not applicable | M11: 10 questions across four assistants | O11: 103 analyzable responses | P11: 103 responses | Q11: Across assistants/questions | R11: Point-in-time test | S11: Accuracy and misinformation coding | T11: Not directly measured | U11: Accuracy of vaccination information | V11: None directly measured | W11: None measured | X11: Misinformation risk | Y11: No user behavior or clinical outcome; limited question set; product responses can change over time. | Z11: Moderate | AA11: https://doi.org/10.2196/19018 | AB11: contextual_assistant_benchmark | AC11: Assistant response accuracy is contextual benchmark evidence, not a dedicated healthcare-service intervention. | AD11: Across analyzed responses, 61.2% were accurate and 17.5% contained misinformation, indicating material information-safety limitations. | AE11: Publisher full text; question set, response count and accuracy/misinformation results verified. | AF11: Targeted primary-source check in this revision
A12: S08 | B12: Koman et al. (2020) | C12: 2020 | D12: Information-seeking chatbot prototype | E12: Text chatbot demonstration/interview | F12: Prototype conversational information tool | G12: Professional medical information | H12: Primary/specialist care physicians | I12: France | J12: Physicians | K12: Qualitative interviews | L12: Purposive physician recruitment | M12: 10 | O12: 10 | P12: 8 general practitioners; 2 specialists | Q12: None | R12: Single demonstration and interview | S12: Semi-structured interviews/thematic analysis | T12: Perceived usability, trust and information quality | U12: Potential professional information-seeking support | V12: Possible workflow fit and adoption requirements | W12: None measured | X12: Need for trustworthy and exhaustive responses | Y12: Small localized qualitative sample and prototype exposure; no implementation or performance outcomes. | Z12: Moderate | AA12: https://doi.org/10.2196/15185 | AB12: bounded_healthcare_sample | AD12: Physicians valued conversational tone and ergonomics but emphasized that professional adoption depends on exhaustive, reliable and transparent information. | AE12: Publisher full text; sample composition, design and principal themes verified. | AF12: Targeted primary full text recheck, 23 October 2026: Results: Demographics; Discussion. Scope: 10 French healthcare professionals interviewed about information-seeking chatbot; qualitative user evidence. Not a full independent appraisal. | AG12: Results: Demographics; Discussion
A13: S09 | B13: Daley et al. (2020) | C13: 2020 | D13: Vitalk (Viki) | E13: Instant-messenger text chatbot | F13: Scripted CBT/positive-psychology content with NLU triggers | G13: Mental health | H13: Real-world consumer use | I13: Brazil | J13: Adult Portuguese-speaking users | K13: Uncontrolled real-world pre-post analysis | L13: Voluntary users who installed Vitalk between June and November 2019; retrospective selection of first-phase completers | M13: Not reported; the initial installation/enrollment denominator is unavailable | N13: Not applicable (nonrandomized retrospective analysis) | O13: 3,629 first-phase (30-day) completers | P13: 3,629 completers; anxiety 1,648, depression 1,243, stress 738 | Q13: None | R13: 30-day first program phase | S13: GAD-7, PHQ-9, DASS-21 stress subscale; engagement rate | T13: Engagement and response frequency | U13: Scalable access to self-help content | V13: None directly measured | W13: Pre-post symptom change in anxiety, depression and stress | X13: Crisis-information module and human follow-up pathway described | Y13: Self-selected users, completer analysis, no control, limited demographic data and regression based on observational engagement. | Z13: Lower | AA13: https://doi.org/10.3389/fdgth.2020.576361 | AB13: bounded_healthcare_sample | AC13: 3,629 is the analyzed first-phase completer cohort, not the recruited population. The initial recruitment denominator is not reported. | AD13: Users completing a 30-day program phase showed large pre-post symptom reductions and higher engagement was associated with better anxiety and depression outcomes; without a control group, change cannot be attributed confidently to the chatbot. | AE13: Publisher full text; n = 3,629, 30-day exposure, measures and main pre-post results verified. | AF13: Primary full text rechecked on 23 October 2026: Abstract, Methods—Participants, and Results—Symptom Change; no initial recruitment denominator is reported. | AG13: Abstract; Methods—Participants; Results—Symptom Change
A14: S10 | B14: Cheng and Jiang (2020) | C14: 2020 | D14: AI-powered mental-health chatbot services | E14: User-reported chatbot use | F14: Multiple service platforms | G14: Mental health/crisis communication | H14: Post-disaster mental-health information context | I14: United States | J14: Chatbot users | K14: Cross-sectional survey | L14: Online panel/users with prior chatbot experience | M14: 1,114 | O14: 1,114 | P14: 1,114 | Q14: None | R14: Single survey | S14: Motivation, communicative action and engagement constructs | T14: Motivations, active communication and engagement | U14: Crisis-related information/support engagement | V14: Communication strategy implications | W14: None measured | X14: Sensitive post-disaster context; no clinical safety assessment | Y14: Cross-sectional self-report, retrospective platform use and no clinical outcome or verified usage logs. | Z14: Moderate | AA14: https://doi.org/10.1111/1468-5973.12319 | AB14: bounded_healthcare_sample | AD14: The study linked user motivations and active communicative behaviors with engagement in AI-powered mental-health chatbot services. | AE14: Publisher metadata/abstract and audited reference; sample and analytical focus verified. | AF14: Targeted primary abstract recheck, 23 October 2026: Abstract. Scope: 1114 US participants surveyed; motivation, communication and engagement associations. Detailed attrition not re-extracted. Not a full independent appraisal. | AG14: Abstract
A15: S11 | B15: Judson et al. (2020) | C15: 2020 | D15: COVID-19 employee screening chatbot | E15: Digital screening chatbot | F15: Rule-based screening and escalation workflow | G15: Public health/occupational screening | H15: Large academic health system | I15: United States | J15: Health-system employees and occupational-health teams | K15: Implementation case study | L15: Health-system deployment | M15: Pilot approximately 80 employees; system-wide rollout | O15: Entrance clearance: manual 28; digital 20; queue comparison at peak shift; different operational denominators. | P15: Manual 28 and digital 20 in timed entrance-clearance comparison; no pooled employee denominator. | Q15: Nonrandomized manual-versus-digital entrance-clearance comparison; peak-shift queue comparison during implementation. | R15: Initial pandemic deployment period | S15: Screening volume, workflow and escalation metrics | T15: Access and screening completion | U15: Manual 48 seconds versus digital 8 seconds clearance; peak queue 500 versus 100 seconds. | V15: Direct entrance-clearance and peak-queue timings; extrapolated waiting-hour savings; unquantified staffing/cost assertion. | W15: None evaluated comparatively | X15: Escalation pathways and screening criteria | Y15: Small nonrandomized timing samples; implementation-period confounding; no randomized or multisite A/B evaluation; no comprehensive quantified net-cost-effectiveness comparison. | Z15: Moderate | AA15: https://doi.org/10.1093/jamia/ocaa130 | AB15: bounded_healthcare_sample | AC15: Corrected omission of direct operational time measurements. Observed timings, extrapolated waiting-hour savings and an unquantified staffing/cost assertion are distinguished. | AD15: Observed entrance-clearance and queue times were lower with digital screening. The authors extrapolated more than 15,000 employee waiting hours saved and reported staffing/cost savings, but did not provide a comprehensive quantified net-cost-effectiveness comparison. | AE15: Publisher article/abstract and audited reference; implementation scale and purpose verified. | AF15: Targeted primary full-text recheck, 23 October 2026: Results: Impact on Operations; Discussion: limitations. This is not independent duplicate human extraction. | AG15: Results: Impact on Operations; Discussion: limitations | AH15: Observed entrance-clearance and queue times were lower with digital screening. The authors extrapolated more than 15,000 employee waiting hours saved and reported staffing/cost savings, but did not provide a comprehensive quantified net-cost-effectiveness comparison.
A16: S12 | B16: Prochaska et al. (2021) | C16: 2021 | D16: Woebot for Substance Use Disorders (W-SUDs) | E16: Mobile text relational agent | F16: Scripted therapeutic relational agent | G16: Mental health/substance use | H16: Remote consumer intervention | I16: United States | J16: Adults with problematic substance use | K16: Single-group pre-post intervention | L16: Online recruitment | M16: 3,597 screened; 141 consented; 128 baseline | O16: 51 posttreatment respondents | P16: 101 analytic sample | Q16: None | R16: 8 weeks | S16: Substance use, craving and mental-health self-report measures; usability | T16: Engagement, acceptability and usability | U16: Remote behavioral support feasibility | V16: None directly measured | W16: Pre-post substance-use and related symptom measures | X16: Remote intervention boundaries; no comparative safety evaluation | Y16: No comparator, high attrition, self-report and selected online sample. | Z16: Lower | AA16: https://doi.org/10.2196/24850 | AB16: bounded_healthcare_sample | AD16: Participants who remained in the study reported favorable pre-post changes and usability, but the single-group design and substantial attrition preclude firm effectiveness conclusions. | AE16: Publisher full text/abstract; screening, baseline, analytic and follow-up counts verified. | AF16: Targeted primary full text recheck, 23 October 2026: Abstract; Results: Sample; Table 1. Scope: 101 analytic participants; 51 posttreatment respondents; eight-week single-group intervention with usability and symptom endpoints. Not a full independent appraisal. | AG16: Abstract; Results: Sample; Table 1
A17: S13 | B17: Fan et al. (2021) | C17: 2021 | D17: DoctorBot | E17: Mobile self-diagnosis chatbot | F17: Symptom-input conversational system | G17: Medical information/self-diagnosis | H17: Real-world consumer use | I17: China | J17: Public users | K17: Retrospective real-world case study | L17: Routine users | M17: 16,519 users | O17: 47,684 consultation sessions | P17: 16,519 users / 47,684 sessions | Q17: None | R17: 6 months | S17: Usage logs and user feedback | T17: Utilization, dropout and user concerns | U17: Self-diagnosis consultation patterns | V17: Service design implications | W17: No validated diagnosis outcome in the review extraction | X17: Concerns about actionability and accuracy | Y17: Observational platform data, unclear representativeness and limited clinical ground truth. | Z17: Moderate | AA17: https://doi.org/10.2196/19928 | AB17: bounded_healthcare_sample | AD17: Large-scale usage data showed substantial use but also dropout and user concerns, emphasizing that utilization does not demonstrate diagnostic accuracy or clinical benefit. | AE17: Publisher abstract/full text; user and session counts, period and study purpose verified. | AF17: Targeted primary full text recheck, 23 October 2026: Methods; Results: Utilization. Scope: 16,519 users and 47,684 consultations over six months; usage outcomes do not establish clinical accuracy. Not a full independent appraisal. | AG17: Methods; Results: Utilization
A18: S14 | B18: Sweeney et al. (2021) | C18: 2021 | D18: Generic mental-health chatbots | E18: Professional survey | F18: Not system-specific | G18: Mental health service implementation | H18: Mental-health professional/expert survey | I18: Northern Ireland, Ireland, Scotland, Sweden and Finland | J18: Mental-health professionals and experts | K18: Cross-sectional survey | L18: Professional networks | M18: 100 | O18: 100 | P18: 100 | Q18: None | R18: Single survey | S18: Perception and implementation questionnaire | T18: Professional views of benefits, importance and limitations | U18: Perceived self-management and support potential | V18: Professional readiness and human-care boundaries | W18: None measured | X18: Strong concern about inability to understand emotion | Y18: Self-selected perception study; no deployment or outcome data. | Z18: Moderate | AA18: https://doi.org/10.1145/3453175 | AB18: bounded_healthcare_sample | AD18: Professionals perceived potential benefits and self-management value but emphasized limitations in emotional understanding and the need for human support. | AE18: Publisher abstract/full text; n = 100 and principal professional perceptions verified. | AF18: Targeted author-institution-hosted primary abstract check, 23 October 2026: Abstract. Online survey of mental healthcare professionals and experts; attitudes/perceptions, not a qualitative interview study or observed clinical effect. The inherited n = 100 was not separately re-extracted from full text here. No independent human duplicate assessment.
A19: S15 | B19: Rahman et al. (2021) | C19: 2021 | D19: AdolescentBot | E19: Text chatbot/prototype evaluation | F19: Contextualized conversational prototype | G19: Public health/sexual and reproductive health | H19: Adolescent information support | I19: Bangladesh | J19: Adolescents and medical personnel | K19: Mixed-method formative HCI study | L19: Participants from six regions | M19: 256 | O19: 256 responses/participants reported across study components; no longitudinal completion population established in accessible abstract. | P19: 256 | Q19: None | R19: Formative/prototype study | S19: Interviews, surveys and prototype feedback | T19: Information needs, acceptability and privacy/anonymity preferences | U19: Access to culturally appropriate SRH information | V19: Requirements for connection to trusted services | W19: None measured | X19: Stigma, language, culture and privacy in a low-resource context | Y19: Formative/prototype evidence; no clinical or longitudinal outcome. | Z19: Moderate | AA19: https://doi.org/10.1145/3411764.3445694 | AB19: bounded_healthcare_sample | AD19: The study identified culturally and socially specific requirements for adolescent SRH chatbots, including privacy, understandable language and trustworthy linkage to care. | AE19: Publisher paper/abstract and audited reference; sample, setting and formative focus verified. | AF19: Targeted primary abstract recheck, 23 October 2026: Abstract. Scope: Responses from 256 participants, including adolescents and medical personnel in six Bangladesh regions; prototype communication and experience analysis. Not a full independent appraisal. | AG19: Abstract
A20: S16 | B20: Griffin et al. (2021) | C20: 2021 | D20: Prospective hypertension self-management chatbot concept | E20: Interviews/design activities | F20: Not a deployed clinical chatbot | G20: Chronic-disease medication self-management | H20: Adults with hypertension | I20: United States | J20: Patients | K20: Mixed-method user-needs study | L20: Patient recruitment | M20: 15 | O20: 15 | P20: 15 | Q20: None | R20: Single study encounter | S20: Interviews, questionnaires and design probes | T20: Perceived usefulness, privacy, usability and information needs | U20: Medication refill, communication and accountability support needs | V20: Potential linkage to care teams | W20: None measured | X20: Privacy and information-overload concerns | Y20: Very small sample and concept-level evaluation; no deployed system or outcome. | Z20: Moderate | AA20: https://doi.org/10.1093/jamiaopen/ooab021 | AB20: bounded_healthcare_sample | AD20: Participants wanted medication-management, refill, communication and accountability support, while expressing privacy, usability and information-overload concerns. | AE20: Publisher article/abstract; sample, mixed-method design and principal needs verified. | AF20: Targeted primary full text recheck, 23 October 2026: Methods; Results: Sample characteristics. Scope: 15 participants with hypertension; mixed-method self-management needs and perceptions; not a treatment trial. Not a full independent appraisal. | AG20: Methods; Results: Sample characteristics
A21: S17 | B21: Jang et al. (2021) | C21: 2021 | D21: Todaki | E21: Mobile text chatbot | F21: CBT/psychoeducation chatbot | G21: Mental health/attention deficit | H21: Adult pilot intervention | I21: South Korea | J21: Adults with attention-deficit symptoms | K21: Pilot randomized feasibility/usability study | L21: Adult volunteer sample | M21: 46 | N21: 46 (23/23) | O21: Not established from accessible primary excerpt; randomized and ITT n must not be treated as completer n. | P21: ITT23/23=46; separate endpoint-completion denominator not established. | Q21: Information-only control | R21: 4 weeks | S21: Feasibility, usability and symptom/experience measures | T21: Usability, empathic/friendly character and dialogue naturalness | U21: Remote CBT/psychoeducation feasibility | V21: None directly measured | W21: Exploratory attention-related outcomes | X21: Not powered for safety | Y21: Small short pilot, limited power and no long-term service or clinical outcome. | Z21: Moderate | AA21: https://doi.org/10.1016/j.ijmedinf.2021.104440 | AB21: bounded_healthcare_sample | AD21: The pilot supported feasibility and identified valued empathic/friendly features, while unnatural conversational flow was a recurring limitation. | AE21: Publisher metadata/abstract and source audit; n = 46, group allocation, 4-week duration and usability themes verified. | AF21: Targeted primary abstract and publisher excerpts recheck, 23 October 2026: Abstract: Methods/Results. Scope: 46 randomized 23/23; four-week pilot; ITT analysis 23/23. Endpoint completer count was not established by the accessible excerpt. Not a full independent appraisal. | AG21: Abstract: Methods/Results | AH21: The small randomized pilot measured attention-deficit and associated symptoms plus usability; ITT group-by-time effects favored the intervention on selected attention-deficit scales. Feasibility evidence is not definitive effectiveness.
